#VRML_SIM R2025a utf8
# license: Apache License 2.0
# license url: http://www.apache.org/licenses/LICENSE-2.0
# This is a proto file for Webots for the tankbot
# Extracted from: C:\Apache24\htdocs\personalProjects\FRC9214\2025\code\tankdrive\withSim\solidworks\urdf\tankbot.SLDASM\urdf\tankbot.SLDASM.urdf

PROTO tankbot [
  field  SFVec3f     translation     0 0 0
  field  SFRotation  rotation        0 0 1 0
  field  SFString    name            "tankbot"  # Is `Robot.name`.
  field  SFString    controller      "void"     # Is `Robot.controller`.
  field  MFString    controllerArgs  []         # Is `Robot.controllerArgs`.
  field  SFString    customData      ""         # Is `Robot.customData`.
  field  SFBool      supervisor      FALSE      # Is `Robot.supervisor`.
  field  SFBool      synchronization TRUE      # Changed to FALSE for real‑time operation.
  field  SFBool      selfCollision   FALSE      # Is `Robot.selfCollision`.
]
{
  Robot {
    translation IS translation
    rotation IS rotation
    controller IS controller
    controllerArgs IS controllerArgs
    customData IS customData
    supervisor IS supervisor
    synchronization IS synchronization
    selfCollision IS selfCollision
    children [
      Shape {
        appearance DEF base_link_material PBRAppearance {
          baseColor 0.898039 0.917647 0.929412
          roughness 1.000000
          metalness 0
        }
        geometry DEF base_link Mesh {
          url "C:/Apache24/htdocs/personalProjects/FRC9214/2025/code/tankdrive/withSim/solidworks/urdf/tankbot.SLDASM/meshes/base_link.STL"
        }
      }
      HingeJoint {
        jointParameters HingeJointParameters {
          axis 1 0 0
          anchor -0.0127 -0.1000 0.050711  # left_front pivot, update as needed
        }
        device [
          RotationalMotor {
            name "left_front_joint"
            maxTorque 10000
          }
          PositionSensor {
            name "left_front_joint_sensor"
          }
        ]
        endPoint Solid {
          children [
            Shape {
              appearance DEF left_front_material PBRAppearance {
                roughness 1.000000
                metalness 0
              }
              geometry DEF left_front Mesh {
                url "C:/Apache24/htdocs/personalProjects/FRC9214/2025/code/tankdrive/withSim/solidworks/urdf/tankbot.SLDASM/meshes/left_front.STL"
              }
            }
          ]
          name "left_front"
          boundingObject USE left_front
          physics Physics {
            density -1
            mass 1.032700
            centerOfMass [ -0.012700 -0.100000 0.050711 ]
            inertiaMatrix [
              5.186700e-03 2.648900e-03 2.648900e-03
              2.357900e-19 -1.013400e-19 -2.408200e-19
            ]
          }
        }
      }
      HingeJoint {
        jointParameters HingeJointParameters {
          axis 1 0 0
          anchor -0.0127 -0.9000 0.050711  # left_rear pivot
        }
        device [
          RotationalMotor {
            name "left_rear_joint"
            maxTorque 10000
          }
          PositionSensor {
            name "left_rear_joint_sensor"
          }
        ]
        endPoint Solid {
          children [
            Shape {
              appearance DEF left_rear_material PBRAppearance {
                roughness 1.000000
                metalness 0
              }
              geometry DEF left_rear Mesh {
                url "C:/Apache24/htdocs/personalProjects/FRC9214/2025/code/tankdrive/withSim/solidworks/urdf/tankbot.SLDASM/meshes/left_rear.STL"
              }
            }
          ]
          name "left_rear"
          boundingObject USE left_rear
          physics Physics {
            density -1
            mass 1.032700
            centerOfMass [ -0.012700 -0.900000 0.050711 ]
            inertiaMatrix [
              5.186700e-03 2.648900e-03 2.648900e-03
              -3.196000e-20 -1.717700e-19 -3.104800e-19
            ]
          }
        }
      }
      HingeJoint {
        jointParameters HingeJointParameters {
          axis 1 0 0
          anchor 1.0127 -0.1000 0.050711  # right_front pivot
        }
        device [
          RotationalMotor {
            name "right_front_joint"
            maxTorque 10000
          }
          PositionSensor {
            name "right_front_joint_sensor"
          }
        ]
        endPoint Solid {
          children [
            Shape {
              appearance DEF right_front_material PBRAppearance {
                roughness 1.000000
                metalness 0
              }
              geometry DEF right_front Mesh {
                url "C:/Apache24/htdocs/personalProjects/FRC9214/2025/code/tankdrive/withSim/solidworks/urdf/tankbot.SLDASM/meshes/right_front.STL"
              }
            }
          ]
          name "right_front"
          boundingObject USE right_front
          physics Physics {
            density -1
            mass 1.032700
            centerOfMass [ 1.012700 -0.100000 0.050711 ]
            inertiaMatrix [
              5.186700e-03 2.648900e-03 2.648900e-03
              2.262500e-19 -3.617000e-19 5.307000e-19
            ]
          }
        }
      }
      HingeJoint {
        jointParameters HingeJointParameters {
          axis 1 0 0
          anchor 1.0127 -0.9000 0.050711  # right_rear pivot
        }
        device [
          RotationalMotor {
            name "right_rear_joint"
            maxTorque 10000
          }
          PositionSensor {
            name "right_rear_joint_sensor"
          }
        ]
        endPoint Solid {
          children [
            Shape {
              appearance DEF right_rear_material PBRAppearance {
                roughness 1.000000
                metalness 0
              }
              geometry DEF right_rear Mesh {
                url "C:/Apache24/htdocs/personalProjects/FRC9214/2025/code/tankdrive/withSim/solidworks/urdf/tankbot.SLDASM/meshes/right_rear.STL"
              }
            }
          ]
          name "right_rear"
          boundingObject USE right_rear
          physics Physics {
            density -1
            mass 1.032700
            centerOfMass [ 1.012700 -0.900000 0.050711 ]
            inertiaMatrix [
              5.186700e-03 2.648900e-03 2.648900e-03
              4.229300e-19 -7.065500e-20 -1.071300e-19
            ]
          }
        }
      }
    ]
    name IS name
    boundingObject USE base_link
    physics Physics {
      density -1
      mass 268.303540
      centerOfMass [ 0.500000 -0.500000 0.049996 ]
      inertiaMatrix [
        2.245348e+01 2.258359e+01 4.458715e+01
        2.614665e-15 1.158359e-16 1.325291e-18
      ]
    }
  }
}
