#VRML_SIM R2025a utf8

EXTERNPROTO "https://raw.githubusercontent.com/cyberbotics/webots/R2025a/projects/objects/backgrounds/protos/TexturedBackground.proto"
EXTERNPROTO "https://raw.githubusercontent.com/cyberbotics/webots/R2025a/projects/objects/backgrounds/protos/TexturedBackgroundLight.proto"
EXTERNPROTO "https://raw.githubusercontent.com/cyberbotics/webots/R2025a/projects/objects/floors/protos/RectangleArena.proto"

WorldInfo {
}
Viewpoint {
  orientation 0.0024450540775277254 -0.018697117391980187 0.9998222039501765 1.362385125615611
  position 0.043454985871731674 -0.5302688068692978 0.18616422965892696
}
TexturedBackground {
}
TexturedBackgroundLight {
}
RectangleArena {
  translation 0 0 0.01
  floorSize 5 5
}
Robot {
  children [
    Solid {
      translation 0 0 0.15
      children [
        HingeJoint {
          jointParameters HingeJointParameters {
            axis 0 1 0
          }
          endPoint Solid {
            translation 0.06 -0.01 -0.055
            children [
              Shape {
                appearance PBRAppearance {
                  baseColor 1 0 0
                }
                geometry Mesh {
                  url [
                    "../../solidworks/wheel.STL"
                  ]
                }
              }
            ]
            boundingObject Mesh {
              url [
                "../../solidworks/wheel.STL"
              ]
            }
            physics Physics {
              mass 1
            }
          }
        }
        Shape {
          appearance PBRAppearance {
          }
          geometry Mesh {
            url [
              "../../solidworks/base.STL"
            ]
          }
        }
      ]
      name "BaseSolid"
      boundingObject Mesh {
        url [
          "../../solidworks/base.STL"
        ]
      }
      physics Physics {
        mass 1
      }
    }
  ]
}
